<?xml version="1.0" encoding="utf-8"?>
<!-- This URDF was automatically created by SolidWorks to URDF Exporter! Originally created by Stephen Brawner (brawner@gmail.com) 
     Commit Version: 1.6.0-4-g7f85cfe  Build Version: 1.6.7995.38578
     For more information, please see http://wiki.ros.org/sw_urdf_exporter -->
<robot
  name="berserkers_robot_1">
  <link
    name="Base_link">
    <inertial>
      <origin
        xyz="0 -5.5511E-17 -0.0082879"
        rpy="0 0 0" />
      <mass
        value="1.0329" />
      <inertia
        ixx="0.0049873"
        ixy="-1.4294E-18"
        ixz="1.8699E-19"
        iyy="0.013953"
        iyz="4.062E-19"
        izz="0.018805" />
    </inertial>
    <visual>
      <origin
        xyz="0 0 0"
        rpy="0 0 0" />
      <geometry>
        <mesh
          filename="package://berserkers_robot_1/meshes/Base_link.STL" />
      </geometry>
      <material
        name="">
        <color
          rgba="0.9098 0.44314 0.031373 1" />
      </material>
    </visual>
    <collision>
      <origin
        xyz="0 0 0"
        rpy="0 0 0" />
      <geometry>
        <mesh
          filename="package://berserkers_robot_1/meshes/Base_link.STL" />
      </geometry>
    </collision>
  </link>
  <link
    name="Wheel_A">
    <inertial>
      <origin
        xyz="8.6125E-09 9.6732E-09 0.029559"
        rpy="0 0 0" />
      <mass
        value="0.091411" />
      <inertia
        ixx="0.00014154"
        ixy="-7.027E-11"
        ixz="-1.7909E-11"
        iyy="0.00014154"
        iyz="-2.2393E-11"
        izz="0.00022525" />
    </inertial>
    <visual>
      <origin
        xyz="0 0 0"
        rpy="0 0 0" />
      <geometry>
        <mesh
          filename="package://berserkers_robot_1/meshes/Wheel_A.STL" />
      </geometry>
      <material
        name="">
        <color
          rgba="0.79216 0.81961 0.93333 1" />
      </material>
    </visual>
    <collision>
      <origin
        xyz="0 0 0"
        rpy="0 0 0" />
      <geometry>
        <mesh
          filename="package://berserkers_robot_1/meshes/Wheel_A.STL" />
      </geometry>
    </collision>
  </link>
  <joint
    name="Wheel_AJ"
    type="continuous">
    <origin
      xyz="-0.095 -0.095681 -0.025"
      rpy="1.5708 -0.68203 0" />
    <parent
      link="Base_link" />
    <child
      link="Wheel_A" />
    <axis
      xyz="0 0 1" />
    <limit
      effort="40"
      velocity="40" />
  </joint>
  <link
    name="Wheel_B">
    <inertial>
      <origin
        xyz="-1.0816E-09 -1.2893E-08 0.02832"
        rpy="0 0 0" />
      <mass
        value="0.091411" />
      <inertia
        ixx="0.00014154"
        ixy="1.2429E-11"
        ixz="-3.9088E-12"
        iyy="0.00014154"
        iyz="-2.8402E-11"
        izz="0.00022525" />
    </inertial>
    <visual>
      <origin
        xyz="0 0 0"
        rpy="0 0 0" />
      <geometry>
        <mesh
          filename="package://berserkers_robot_1/meshes/Wheel_B.STL" />
      </geometry>
      <material
        name="">
        <color
          rgba="0.79216 0.81961 0.93333 1" />
      </material>
    </visual>
    <collision>
      <origin
        xyz="0 0 0"
        rpy="0 0 0" />
      <geometry>
        <mesh
          filename="package://berserkers_robot_1/meshes/Wheel_B.STL" />
      </geometry>
    </collision>
  </link>
  <joint
    name="Wheel_BJ"
    type="continuous">
    <origin
      xyz="-0.095 0.15356 -0.025"
      rpy="1.5708 0.40973 0" />
    <parent
      link="Base_link" />
    <child
      link="Wheel_B" />
    <axis
      xyz="0 0 1" />
    <limit
      effort="40"
      velocity="40" />
  </joint>
  <link
    name="Wheel_C">
    <inertial>
      <origin
        xyz="1.0917E-09 -1.2911E-08 0.029559"
        rpy="0 0 0" />
      <mass
        value="0.091411" />
      <inertia
        ixx="0.00014154"
        ixy="-1.2429E-11"
        ixz="-3.9125E-12"
        iyy="0.00014154"
        iyz="2.8407E-11"
        izz="0.00022525" />
    </inertial>
    <visual>
      <origin
        xyz="0 0 0"
        rpy="0 0 0" />
      <geometry>
        <mesh
          filename="package://berserkers_robot_1/meshes/Wheel_C.STL" />
      </geometry>
      <material
        name="">
        <color
          rgba="0.79216 0.81961 0.93333 1" />
      </material>
    </visual>
    <collision>
      <origin
        xyz="0 0 0"
        rpy="0 0 0" />
      <geometry>
        <mesh
          filename="package://berserkers_robot_1/meshes/Wheel_C.STL" />
      </geometry>
    </collision>
  </link>
  <joint
    name="Wheel_CJ"
    type="continuous">
    <origin
      xyz="0.095 -0.095681 -0.025"
      rpy="1.5708 -0.57539 0" />
    <parent
      link="Base_link" />
    <child
      link="Wheel_C" />
    <axis
      xyz="0 0 1" />
    <limit
      effort="40"
      velocity="40" />
  </joint>
  <link
    name="Wheel_D">
    <inertial>
      <origin
        xyz="-1.0725E-09 -1.2907E-08 0.02832"
        rpy="0 0 0" />
      <mass
        value="0.091411" />
      <inertia
        ixx="0.00014154"
        ixy="1.2427E-11"
        ixz="-3.9063E-12"
        iyy="0.00014154"
        iyz="-2.8406E-11"
        izz="0.00022525" />
    </inertial>
    <visual>
      <origin
        xyz="0 0 0"
        rpy="0 0 0" />
      <geometry>
        <mesh
          filename="package://berserkers_robot_1/meshes/Wheel_D.STL" />
      </geometry>
      <material
        name="">
        <color
          rgba="0.79216 0.81961 0.93333 1" />
      </material>
    </visual>
    <collision>
      <origin
        xyz="0 0 0"
        rpy="0 0 0" />
      <geometry>
        <mesh
          filename="package://berserkers_robot_1/meshes/Wheel_D.STL" />
      </geometry>
    </collision>
  </link>
  <joint
    name="Wheel_DJ"
    type="continuous">
    <origin
      xyz="0.095 0.15356 -0.025"
      rpy="1.5708 1.024 0" />
    <parent
      link="Base_link" />
    <child
      link="Wheel_D" />
    <axis
      xyz="0 0 1" />
    <limit
      effort="40"
      velocity="40" />
  </joint>

        <gazebo>
    <plugin name="differential_drive_controller" filename="libgazebo_ros_diff_drive.so">
        <legacyMode>false</legacyMode>
        <alwaysOn>true</alwaysOn>
        <publishWheelTF>true</publishWheelTF>
        <publishTf>1</publishTf>
        <publishWheelJointState>true</publishWheelJointState>
        <updateRate>100.0</updateRate>
        <leftJoint>Wheel_AJ</leftJoint>
        <rightJoint>Wheel_BJ</rightJoint>
        <wheelSeparation>0.195</wheelSeparation>
        <wheelDiameter>0.125</wheelDiameter>
        <wheelAcceleration>0.5</wheelAcceleration>
        <torque>0.5</torque>
        <commandTopic>cmd_vel</commandTopic>
        <odometryTopic>odom</odometryTopic>
        <odometryFrame>odom</odometryFrame>
        <robotBaseFrame>Base_link</robotBaseFrame>
    </plugin>
</gazebo>

</robot>